<?xml version="1.0" encoding="utf-8"?>
<!-- AUTO-GENERATED by build_urdf.py: xArm7 arm + XHand right (19 DOF). Do not edit by hand. -->
<robot name="xarm7_xhand">


  <!-- ===================== Links ===================== -->
  <link name="link_base">
    <visual>
      <origin xyz="0 0 0" rpy="0 0 0"/>
      <geometry>
        <mesh filename="meshes/link_base.stl"/>
      </geometry>
    </visual>
    <collision>
      <origin xyz="0 0 0" rpy="0 0 0"/>
      <geometry>
        <mesh filename="meshes/link_base.stl"/>
      </geometry>
    </collision>
    <inertial>
      <origin xyz="0 0 0" rpy="0 0 0"/>
      <mass value="1.0"/>
      <inertia ixx="0.01" ixy="0" ixz="0" iyy="0.01" iyz="0" izz="0.01"/>
    </inertial>
  </link>

  <link name="link1">
    <visual>
      <origin xyz="0 0 0" rpy="0 0 0"/>
      <geometry>
        <mesh filename="meshes/link1.stl"/>
      </geometry>
    </visual>
    <collision>
      <origin xyz="0 0 0" rpy="0 0 0"/>
      <geometry>
        <mesh filename="meshes/link1.stl"/>
      </geometry>
    </collision>
    <inertial>
      <origin xyz="0 0 0" rpy="0 0 0"/>
      <mass value="1.0"/>
      <inertia ixx="0.01" ixy="0" ixz="0" iyy="0.01" iyz="0" izz="0.01"/>
    </inertial>
  </link>

  <link name="link2">
    <visual>
      <origin xyz="0 0 0" rpy="0 0 0"/>
      <geometry>
        <mesh filename="meshes/link2.stl"/>
      </geometry>
    </visual>
    <collision>
      <origin xyz="0 0 0" rpy="0 0 0"/>
      <geometry>
        <mesh filename="meshes/link2.stl"/>
      </geometry>
    </collision>
    <inertial>
      <origin xyz="0 0 0" rpy="0 0 0"/>
      <mass value="1.0"/>
      <inertia ixx="0.01" ixy="0" ixz="0" iyy="0.01" iyz="0" izz="0.01"/>
    </inertial>
  </link>

  <link name="link3">
    <visual>
      <origin xyz="0 0 0" rpy="0 0 0"/>
      <geometry>
        <mesh filename="meshes/link3.stl"/>
      </geometry>
    </visual>
    <collision>
      <origin xyz="0 0 0" rpy="0 0 0"/>
      <geometry>
        <mesh filename="meshes/link3.stl"/>
      </geometry>
    </collision>
    <inertial>
      <origin xyz="0 0 0" rpy="0 0 0"/>
      <mass value="1.0"/>
      <inertia ixx="0.01" ixy="0" ixz="0" iyy="0.01" iyz="0" izz="0.01"/>
    </inertial>
  </link>

  <link name="link4">
    <visual>
      <origin xyz="0 0 0" rpy="0 0 0"/>
      <geometry>
        <mesh filename="meshes/link4.stl"/>
      </geometry>
    </visual>
    <collision>
      <origin xyz="0 0 0" rpy="0 0 0"/>
      <geometry>
        <mesh filename="meshes/link4.stl"/>
      </geometry>
    </collision>
    <inertial>
      <origin xyz="0 0 0" rpy="0 0 0"/>
      <mass value="1.0"/>
      <inertia ixx="0.01" ixy="0" ixz="0" iyy="0.01" iyz="0" izz="0.01"/>
    </inertial>
  </link>

  <link name="link5">
    <visual>
      <origin xyz="0 0 0" rpy="0 0 0"/>
      <geometry>
        <mesh filename="meshes/link5.stl"/>
      </geometry>
    </visual>
    <collision>
      <origin xyz="0 0 0" rpy="0 0 0"/>
      <geometry>
        <mesh filename="meshes/link5.stl"/>
      </geometry>
    </collision>
    <inertial>
      <origin xyz="0 0 0" rpy="0 0 0"/>
      <mass value="1.0"/>
      <inertia ixx="0.01" ixy="0" ixz="0" iyy="0.01" iyz="0" izz="0.01"/>
    </inertial>
  </link>

  <link name="link6">
    <visual>
      <origin xyz="0 0 0" rpy="0 0 0"/>
      <geometry>
        <mesh filename="meshes/link6.stl"/>
      </geometry>
    </visual>
    <collision>
      <origin xyz="0 0 0" rpy="0 0 0"/>
      <geometry>
        <mesh filename="meshes/link6.stl"/>
      </geometry>
    </collision>
    <inertial>
      <origin xyz="0 0 0" rpy="0 0 0"/>
      <mass value="1.0"/>
      <inertia ixx="0.01" ixy="0" ixz="0" iyy="0.01" iyz="0" izz="0.01"/>
    </inertial>
  </link>

  <link name="link7">
    <visual>
      <origin xyz="0 0 0" rpy="0 0 0"/>
      <geometry>
        <mesh filename="meshes/link7.stl"/>
      </geometry>
    </visual>
    <collision>
      <origin xyz="0 0 0" rpy="0 0 0"/>
      <geometry>
        <mesh filename="meshes/link7.stl"/>
      </geometry>
    </collision>
    <inertial>
      <origin xyz="0 0 0" rpy="0 0 0"/>
      <mass value="1.0"/>
      <inertia ixx="0.01" ixy="0" ixz="0" iyy="0.01" iyz="0" izz="0.01"/>
    </inertial>
  </link>

  <!-- ===================== Joints ===================== -->
  <joint name="joint1" type="revolute">
    <origin xyz="0 0 0.267" rpy="0 0 0"/>
    <parent link="link_base"/>
    <child link="link1"/>
    <axis xyz="0 0 1"/>
    <limit lower="-3.14159265" upper="3.14159265" effort="50.0" velocity="3.14"/>
  </joint>

  <joint name="joint2" type="revolute">
    <origin xyz="0 0 0" rpy="-1.5708 0 0"/>
    <parent link="link1"/>
    <child link="link2"/>
    <axis xyz="0 0 1"/>
    <limit lower="-2.18" upper="2.18" effort="50.0" velocity="3.14"/>
  </joint>

  <joint name="joint3" type="revolute">
    <origin xyz="0 -0.293 0" rpy="1.5708 0 0"/>
    <parent link="link2"/>
    <child link="link3"/>
    <axis xyz="0 0 1"/>
    <limit lower="-3.14159265" upper="3.14159265" effort="30.0" velocity="3.14"/>
  </joint>

  <joint name="joint4" type="revolute">
    <origin xyz="0.0525 0 0" rpy="1.5708 0 0"/>
    <parent link="link3"/>
    <child link="link4"/>
    <axis xyz="0 0 1"/>
    <limit lower="-0.11" upper="3.14159265" effort="30.0" velocity="3.14"/>
  </joint>

  <joint name="joint5" type="revolute">
    <origin xyz="0.0775 -0.3425 0" rpy="1.5708 0 0"/>
    <parent link="link4"/>
    <child link="link5"/>
    <axis xyz="0 0 1"/>
    <limit lower="-3.14159265" upper="3.14159265" effort="30.0" velocity="3.14"/>
  </joint>

  <joint name="joint6" type="revolute">
    <origin xyz="0 0 0" rpy="1.5708 0 0"/>
    <parent link="link5"/>
    <child link="link6"/>
    <axis xyz="0 0 1"/>
    <limit lower="-1.75" upper="3.14159265" effort="20.0" velocity="3.14"/>
  </joint>

  <joint name="joint7" type="revolute">
    <origin xyz="0.076 0.097 0" rpy="-1.5708 0 0"/>
    <parent link="link6"/>
    <child link="link7"/>
    <axis xyz="0 0 1"/>
    <limit lower="-3.14159265" upper="3.14159265" effort="20.0" velocity="3.14"/>
  </joint>



  <!-- ===================== Flange frame + hand mount ===================== -->
  <link name="link8" />
  <joint name="link8_joint" type="fixed">
    <origin xyz="0 0 0.0" rpy="0 0 0"/>
    <parent link="link7"/>
    <child link="link8"/>
  </joint>

<material name="dim_gray">
    <color rgba="0.412 0.412 0.412 1.0" />
  </material>
  <material name="gray">
    <color rgba="0.67 0.67 0.67 1.0" />
  </material>

  
  <link name="palm">
    <visual>
      <origin xyz="0 0 0" rpy="0 0 0" />
      <geometry>
        <mesh filename="../xhand2R32/meshes/right_hand_link_.stl" />
      </geometry>
      <material name="dim_gray" />
    </visual>
    <collision>
      <origin xyz="0 0 0" rpy="0 0 0" />
      <geometry>
        <mesh filename="../xhand2R32/meshes/right_hand_link_.stl" />
      </geometry>
    </collision>
  </link>

  
  <link name="thumb_bend_link">
    <visual>
      <origin xyz="0 0 0" rpy="0 0 0" />
      <geometry>
        <mesh filename="../xhand2R32/meshes/right_hand_thumb_bend_link_.stl" />
      </geometry>
      <material name="gray" />
    </visual>
    <collision>
      <origin xyz="0 0 0" rpy="0 0 0" />
      <geometry>
        <mesh filename="../xhand2R32/meshes/right_hand_thumb_bend_link_.stl" />
      </geometry>
    </collision>
  </link>
  <link name="thumb_rota_link1">
    <visual>
      <origin xyz="0 0 0" rpy="0 0 0" />
      <geometry>
        <mesh filename="../xhand2R32/meshes/right_hand_thumb_rota_link1_.stl" />
      </geometry>
      <material name="gray" />
    </visual>
    <collision>
      <origin xyz="0 0 0" rpy="0 0 0" />
      <geometry>
        <mesh filename="../xhand2R32/meshes/right_hand_thumb_rota_link1_.stl" />
      </geometry>
    </collision>
  </link>
  <link name="thumb_rota_link2">
    <visual>
      <origin xyz="0 0 0" rpy="0 0 0" />
      <geometry>
        <mesh filename="../xhand2R32/meshes/right_hand_thumb_rota_link2_.stl" />
      </geometry>
      <material name="gray" />
    </visual>
    <collision>
      <origin xyz="0 0 0" rpy="0 0 0" />
      <geometry>
        <mesh filename="../xhand2R32/meshes/right_hand_thumb_rota_link2_.stl" />
      </geometry>
    </collision>
  </link>

  <joint name="thumb_joint0" type="revolute">
    <parent link="palm" />
    <child link="thumb_bend_link" />
    <origin xyz="0.0228 -0.0095 0.0305" rpy="0 0 0" />
    <axis xyz="0 0 -1" />
    <limit lower="0.0" upper="1.83" effort="10" velocity="3.14" />
  </joint>
  <joint name="thumb_joint1" type="revolute">
    <parent link="thumb_bend_link" />
    <child link="thumb_rota_link1" />
    <origin xyz="0.028599 0.0083177 0.00178" rpy="0.2618 0 0.0407" />
    <axis xyz="0 -1 0" />
    <limit lower="-1.05" upper="1.57" effort="10" velocity="3.14" />
  </joint>
  <joint name="thumb_joint2" type="revolute">
    <parent link="thumb_rota_link1" />
    <child link="thumb_rota_link2" />
    <origin xyz="0.0553 0 0" rpy="0 0 0" />
    <axis xyz="0 -1 0" />
    <limit lower="-0.175" upper="1.83" effort="10" velocity="3.14" />
  </joint>

  
  <link name="index_bend_link">
    <visual>
      <origin xyz="0 0 0" rpy="0 0 0" />
      <geometry>
        <mesh filename="../xhand2R32/meshes/right_hand_index_bend_link_.stl" />
      </geometry>
      <material name="gray" />
    </visual>
    <collision>
      <origin xyz="0 0 0" rpy="0 0 0" />
      <geometry>
        <mesh filename="../xhand2R32/meshes/right_hand_index_bend_link_.stl" />
      </geometry>
    </collision>
  </link>
  <link name="index_rota_link1">
    <visual>
      <origin xyz="0 0 0" rpy="0 0 0" />
      <geometry>
        <mesh filename="../xhand2R32/meshes/right_hand_index_rota_link1_.stl" />
      </geometry>
      <material name="gray" />
    </visual>
    <collision>
      <origin xyz="0 0 0" rpy="0 0 0" />
      <geometry>
        <mesh filename="../xhand2R32/meshes/right_hand_index_rota_link1_.stl" />
      </geometry>
    </collision>
  </link>
  <link name="index_rota_link2">
    <visual>
      <origin xyz="0 0 0" rpy="0 0 0" />
      <geometry>
        <mesh filename="../xhand2R32/meshes/right_hand_index_rota_link2_.stl" />
      </geometry>
      <material name="gray" />
    </visual>
    <collision>
      <origin xyz="0 0 0" rpy="0 0 0" />
      <geometry>
        <mesh filename="../xhand2R32/meshes/right_hand_index_rota_link2_.stl" />
      </geometry>
    </collision>
  </link>

  <joint name="index_joint0" type="revolute">
    <parent link="palm" />
    <child link="index_bend_link" />
    <origin xyz="0.0265 -0.0065 0.0899" rpy="0 0 0" />
    <axis xyz="0 1 0" />
    <limit lower="-0.175" upper="0.175" effort="10" velocity="3.14" />
  </joint>
  <joint name="index_joint1" type="revolute">
    <parent link="index_bend_link" />
    <child link="index_rota_link1" />
    <origin xyz="0 0 0.0178" rpy="0 0 0" />
    <axis xyz="1 0 0" />
    <limit lower="0.0" upper="1.92" effort="10" velocity="3.14" />
  </joint>
  <joint name="index_joint2" type="revolute">
    <parent link="index_rota_link1" />
    <child link="index_rota_link2" />
    <origin xyz="0 0 0.0558" rpy="0 0 0" />
    <axis xyz="1 0 0" />
    <limit lower="0.0" upper="1.92" effort="10" velocity="3.14" />
  </joint>

  
  <link name="mid_link1">
    <visual>
      <origin xyz="0 0 0" rpy="0 0 0" />
      <geometry>
        <mesh filename="../xhand2R32/meshes/right_hand_mid_link1_.stl" />
      </geometry>
      <material name="gray" />
    </visual>
    <collision>
      <origin xyz="0 0 0" rpy="0 0 0" />
      <geometry>
        <mesh filename="../xhand2R32/meshes/right_hand_mid_link1_.stl" />
      </geometry>
    </collision>
  </link>
  <link name="mid_link2">
    <visual>
      <origin xyz="0 0 0" rpy="0 0 0" />
      <geometry>
        <mesh filename="../xhand2R32/meshes/right_hand_mid_link2_.stl" />
      </geometry>
      <material name="gray" />
    </visual>
    <collision>
      <origin xyz="0 0 0" rpy="0 0 0" />
      <geometry>
        <mesh filename="../xhand2R32/meshes/right_hand_mid_link2_.stl" />
      </geometry>
    </collision>
  </link>

  <joint name="middle_joint0" type="revolute">
    <parent link="palm" />
    <child link="mid_link1" />
    <origin xyz="0.004 -0.0065 0.1082" rpy="0 0 0" />
    <axis xyz="1 0 0" />
    <limit lower="0.0" upper="1.92" effort="10" velocity="3.14" />
  </joint>
  <joint name="middle_joint1" type="revolute">
    <parent link="mid_link1" />
    <child link="mid_link2" />
    <origin xyz="0 0 0.0558" rpy="0 0 0" />
    <axis xyz="1 0 0" />
    <limit lower="0.0" upper="1.92" effort="10" velocity="3.14" />
  </joint>

  
  <link name="ring_link1">
    <visual>
      <origin xyz="0 0 0" rpy="0 0 0" />
      <geometry>
        <mesh filename="../xhand2R32/meshes/right_hand_ring_link1_.stl" />
      </geometry>
      <material name="gray" />
    </visual>
    <collision>
      <origin xyz="0 0 0" rpy="0 0 0" />
      <geometry>
        <mesh filename="../xhand2R32/meshes/right_hand_ring_link1_.stl" />
      </geometry>
    </collision>
  </link>
  <link name="ring_link2">
    <visual>
      <origin xyz="0 0 0" rpy="0 0 0" />
      <geometry>
        <mesh filename="../xhand2R32/meshes/right_hand_ring_link2_.stl" />
      </geometry>
      <material name="gray" />
    </visual>
    <collision>
      <origin xyz="0 0 0" rpy="0 0 0" />
      <geometry>
        <mesh filename="../xhand2R32/meshes/right_hand_ring_link2_.stl" />
      </geometry>
    </collision>
  </link>

  <joint name="ring_joint0" type="revolute">
    <parent link="palm" />
    <child link="ring_link1" />
    <origin xyz="-0.016 -0.0065 0.1052" rpy="0 0 0" />
    <axis xyz="1 0 0" />
    <limit lower="0.0" upper="1.92" effort="10" velocity="3.14" />
  </joint>
  <joint name="ring_joint1" type="revolute">
    <parent link="ring_link1" />
    <child link="ring_link2" />
    <origin xyz="0 0 0.0558" rpy="0 0 0" />
    <axis xyz="1 0 0" />
    <limit lower="0.0" upper="1.92" effort="10" velocity="3.14" />
  </joint>

  
  <link name="pinky_link1">
    <visual>
      <origin xyz="0 0 0" rpy="0 0 0" />
      <geometry>
        <mesh filename="../xhand2R32/meshes/right_hand_pinky_link1_.stl" />
      </geometry>
      <material name="gray" />
    </visual>
    <collision>
      <origin xyz="0 0 0" rpy="0 0 0" />
      <geometry>
        <mesh filename="../xhand2R32/meshes/right_hand_pinky_link1_.stl" />
      </geometry>
    </collision>
  </link>
  <link name="pinky_link2">
    <visual>
      <origin xyz="0 0 0" rpy="0 0 0" />
      <geometry>
        <mesh filename="../xhand2R32/meshes/right_hand_pinky_link2_.stl" />
      </geometry>
      <material name="gray" />
    </visual>
    <collision>
      <origin xyz="0 0 0" rpy="0 0 0" />
      <geometry>
        <mesh filename="../xhand2R32/meshes/right_hand_pinky_link2_.stl" />
      </geometry>
    </collision>
  </link>

  <joint name="pinky_joint0" type="revolute">
    <parent link="palm" />
    <child link="pinky_link1" />
    <origin xyz="-0.036 -0.0065 0.1022" rpy="0 0 0" />
    <axis xyz="1 0 0" />
    <limit lower="0.0" upper="1.92" effort="10" velocity="3.14" />
  </joint>
  <joint name="pinky_joint1" type="revolute">
    <parent link="pinky_link1" />
    <child link="pinky_link2" />
    <origin xyz="0 0 0.0558" rpy="0 0 0" />
    <axis xyz="1 0 0" />
    <limit lower="0.0" upper="1.92" effort="10" velocity="3.14" />
  </joint>

<joint name="hand_mount" type="fixed"><parent link="link8" /><child link="palm" /><origin xyz="0 0 0" rpy="0 0 4.71239" /></joint>
</robot>
