<?xml version="1.0"?>
<!-- Generated by build_urdf.py. -->
<robot name="xarm7_gripper">
  <!-- ===================== Links ===================== -->
  <link name="link_base">
    <visual>
      <origin xyz="0 0 0" rpy="0 0 0"/>
      <geometry>
        <mesh filename="../xarm7_xhand/meshes/link_base.stl"/>
      </geometry>
    </visual>
    <collision>
      <origin xyz="0 0 0" rpy="0 0 0"/>
      <geometry>
        <mesh filename="../xarm7_xhand/meshes/link_base.stl"/>
      </geometry>
    </collision>
    <inertial>
      <origin xyz="0 0 0" rpy="0 0 0"/>
      <mass value="1.0"/>
      <inertia ixx="0.01" ixy="0" ixz="0" iyy="0.01" iyz="0" izz="0.01"/>
    </inertial>
  </link>

  <link name="link1">
    <visual>
      <origin xyz="0 0 0" rpy="0 0 0"/>
      <geometry>
        <mesh filename="../xarm7_xhand/meshes/link1.stl"/>
      </geometry>
    </visual>
    <collision>
      <origin xyz="0 0 0" rpy="0 0 0"/>
      <geometry>
        <mesh filename="../xarm7_xhand/meshes/link1.stl"/>
      </geometry>
    </collision>
    <inertial>
      <origin xyz="0 0 0" rpy="0 0 0"/>
      <mass value="1.0"/>
      <inertia ixx="0.01" ixy="0" ixz="0" iyy="0.01" iyz="0" izz="0.01"/>
    </inertial>
  </link>

  <link name="link2">
    <visual>
      <origin xyz="0 0 0" rpy="0 0 0"/>
      <geometry>
        <mesh filename="../xarm7_xhand/meshes/link2.stl"/>
      </geometry>
    </visual>
    <collision>
      <origin xyz="0 0 0" rpy="0 0 0"/>
      <geometry>
        <mesh filename="../xarm7_xhand/meshes/link2.stl"/>
      </geometry>
    </collision>
    <inertial>
      <origin xyz="0 0 0" rpy="0 0 0"/>
      <mass value="1.0"/>
      <inertia ixx="0.01" ixy="0" ixz="0" iyy="0.01" iyz="0" izz="0.01"/>
    </inertial>
  </link>

  <link name="link3">
    <visual>
      <origin xyz="0 0 0" rpy="0 0 0"/>
      <geometry>
        <mesh filename="../xarm7_xhand/meshes/link3.stl"/>
      </geometry>
    </visual>
    <collision>
      <origin xyz="0 0 0" rpy="0 0 0"/>
      <geometry>
        <mesh filename="../xarm7_xhand/meshes/link3.stl"/>
      </geometry>
    </collision>
    <inertial>
      <origin xyz="0 0 0" rpy="0 0 0"/>
      <mass value="1.0"/>
      <inertia ixx="0.01" ixy="0" ixz="0" iyy="0.01" iyz="0" izz="0.01"/>
    </inertial>
  </link>

  <link name="link4">
    <visual>
      <origin xyz="0 0 0" rpy="0 0 0"/>
      <geometry>
        <mesh filename="../xarm7_xhand/meshes/link4.stl"/>
      </geometry>
    </visual>
    <collision>
      <origin xyz="0 0 0" rpy="0 0 0"/>
      <geometry>
        <mesh filename="../xarm7_xhand/meshes/link4.stl"/>
      </geometry>
    </collision>
    <inertial>
      <origin xyz="0 0 0" rpy="0 0 0"/>
      <mass value="1.0"/>
      <inertia ixx="0.01" ixy="0" ixz="0" iyy="0.01" iyz="0" izz="0.01"/>
    </inertial>
  </link>

  <link name="link5">
    <visual>
      <origin xyz="0 0 0" rpy="0 0 0"/>
      <geometry>
        <mesh filename="../xarm7_xhand/meshes/link5.stl"/>
      </geometry>
    </visual>
    <collision>
      <origin xyz="0 0 0" rpy="0 0 0"/>
      <geometry>
        <mesh filename="../xarm7_xhand/meshes/link5.stl"/>
      </geometry>
    </collision>
    <inertial>
      <origin xyz="0 0 0" rpy="0 0 0"/>
      <mass value="1.0"/>
      <inertia ixx="0.01" ixy="0" ixz="0" iyy="0.01" iyz="0" izz="0.01"/>
    </inertial>
  </link>

  <link name="link6">
    <visual>
      <origin xyz="0 0 0" rpy="0 0 0"/>
      <geometry>
        <mesh filename="../xarm7_xhand/meshes/link6.stl"/>
      </geometry>
    </visual>
    <collision>
      <origin xyz="0 0 0" rpy="0 0 0"/>
      <geometry>
        <mesh filename="../xarm7_xhand/meshes/link6.stl"/>
      </geometry>
    </collision>
    <inertial>
      <origin xyz="0 0 0" rpy="0 0 0"/>
      <mass value="1.0"/>
      <inertia ixx="0.01" ixy="0" ixz="0" iyy="0.01" iyz="0" izz="0.01"/>
    </inertial>
  </link>

  <link name="link7">
    <visual>
      <origin xyz="0 0 0" rpy="0 0 0"/>
      <geometry>
        <mesh filename="../xarm7_xhand/meshes/link7.stl"/>
      </geometry>
    </visual>
    <collision>
      <origin xyz="0 0 0" rpy="0 0 0"/>
      <geometry>
        <mesh filename="../xarm7_xhand/meshes/link7.stl"/>
      </geometry>
    </collision>
    <inertial>
      <origin xyz="0 0 0" rpy="0 0 0"/>
      <mass value="1.0"/>
      <inertia ixx="0.01" ixy="0" ixz="0" iyy="0.01" iyz="0" izz="0.01"/>
    </inertial>
  </link>

  <!-- ===================== Joints ===================== -->
  <joint name="joint1" type="revolute">
    <origin xyz="0 0 0.267" rpy="0 0 0"/>
    <parent link="link_base"/>
    <child link="link1"/>
    <axis xyz="0 0 1"/>
    <limit lower="-3.14159265" upper="3.14159265" effort="50.0" velocity="3.14"/>
  </joint>

  <joint name="joint2" type="revolute">
    <origin xyz="0 0 0" rpy="-1.5708 0 0"/>
    <parent link="link1"/>
    <child link="link2"/>
    <axis xyz="0 0 1"/>
    <limit lower="-2.18" upper="2.18" effort="50.0" velocity="3.14"/>
  </joint>

  <joint name="joint3" type="revolute">
    <origin xyz="0 -0.293 0" rpy="1.5708 0 0"/>
    <parent link="link2"/>
    <child link="link3"/>
    <axis xyz="0 0 1"/>
    <limit lower="-3.14159265" upper="3.14159265" effort="30.0" velocity="3.14"/>
  </joint>

  <joint name="joint4" type="revolute">
    <origin xyz="0.0525 0 0" rpy="1.5708 0 0"/>
    <parent link="link3"/>
    <child link="link4"/>
    <axis xyz="0 0 1"/>
    <limit lower="-0.11" upper="3.14159265" effort="30.0" velocity="3.14"/>
  </joint>

  <joint name="joint5" type="revolute">
    <origin xyz="0.0775 -0.3425 0" rpy="1.5708 0 0"/>
    <parent link="link4"/>
    <child link="link5"/>
    <axis xyz="0 0 1"/>
    <limit lower="-3.14159265" upper="3.14159265" effort="30.0" velocity="3.14"/>
  </joint>

  <joint name="joint6" type="revolute">
    <origin xyz="0 0 0" rpy="1.5708 0 0"/>
    <parent link="link5"/>
    <child link="link6"/>
    <axis xyz="0 0 1"/>
    <limit lower="-1.75" upper="3.14159265" effort="20.0" velocity="3.14"/>
  </joint>

  <joint name="joint7" type="revolute">
    <origin xyz="0.076 0.097 0" rpy="-1.5708 0 0"/>
    <parent link="link6"/>
    <child link="link7"/>
    <axis xyz="0 0 1"/>
    <limit lower="-3.14159265" upper="3.14159265" effort="20.0" velocity="3.14"/>
  </joint>



  <!-- ===================== Flange frame + hand mount ===================== -->
  <link name="link8" />
  <joint name="link8_joint" type="fixed">
    <origin xyz="0 0 0.0" rpy="0 0 0"/>
    <parent link="link7"/>
    <child link="link8"/>
  </joint>


  <material name="gripper_dark"><color rgba="0.18 0.18 0.20 1"/></material>
  <material name="pad_rubber"><color rgba="0.05 0.05 0.05 1"/></material>

  <link name="palm">
    <visual><origin xyz="0 0 0.025"/><geometry><box size="0.10 0.055 0.05"/></geometry><material name="gripper_dark"/></visual>
    <collision><origin xyz="0 0 0.025"/><geometry><box size="0.10 0.055 0.05"/></geometry></collision>
    <inertial><origin xyz="0 0 0.025"/><mass value="0.30"/><inertia ixx="0.0002" ixy="0" ixz="0" iyy="0.0002" iyz="0" izz="0.0002"/></inertial>
  </link>
  <joint name="hand_mount" type="fixed">
    <origin xyz="0 0 0" rpy="0 0 4.71239"/>
    <parent link="link8"/><child link="palm"/>
  </joint>

  <link name="thumb_rota_link2">
    <visual><origin xyz="0 0 0.045"/><geometry><box size="0.014 0.035 0.09"/></geometry><material name="pad_rubber"/></visual>
    <collision><origin xyz="0 0 0.045"/><geometry><box size="0.014 0.035 0.09"/></geometry></collision>
    <inertial><origin xyz="0 0 0.045"/><mass value="0.08"/><inertia ixx="0.00006" ixy="0" ixz="0" iyy="0.00006" iyz="0" izz="0.00001"/></inertial>
  </link>
  <joint name="left_finger_joint" type="prismatic">
    <origin xyz="0 0 0.045"/><parent link="palm"/><child link="thumb_rota_link2"/><axis xyz="1 0 0"/>
    <limit lower="0.0" upper="0.055" effort="120" velocity="0.25"/>
  </joint>

  <link name="index_rota_link2">
    <visual><origin xyz="0 0 0.045"/><geometry><box size="0.014 0.035 0.09"/></geometry><material name="pad_rubber"/></visual>
    <collision><origin xyz="0 0 0.045"/><geometry><box size="0.014 0.035 0.09"/></geometry></collision>
    <inertial><origin xyz="0 0 0.045"/><mass value="0.08"/><inertia ixx="0.00006" ixy="0" ixz="0" iyy="0.00006" iyz="0" izz="0.00001"/></inertial>
  </link>
  <joint name="right_finger_joint" type="prismatic">
    <origin xyz="0 0 0.045"/><parent link="palm"/><child link="index_rota_link2"/><axis xyz="-1 0 0"/>
    <limit lower="0.0" upper="0.055" effort="120" velocity="0.25"/>
  </joint>

</robot>
